<?xml version="1.0" encoding="UTF-8"?>
<!-- Generated by org.testng.reporters.JUnitXMLReporter -->
<testsuite hostname="LAPTOP-CEPNQT7N" name="Sequence Test" tests="3" failures="1" timestamp="5 Mar 2017 13:05:04 GMT" time="0.014" errors="0">
  <testcase name="f1" time="0.0" classname="TestNGAnnotations.AnnotationSequence">
    <failure type="java.lang.Exception" message="This is custom exception message">
      <![CDATA[java.lang.Exception: This is custom exception message
	at TestNGAnnotations.AnnotationSequence.f1(AnnotationSequence.java:32)
	at java.util.concurrent.ThreadPoolExecutor.runWorker(ThreadPoolExecutor.java:1142)
	at java.util.concurrent.ThreadPoolExecutor$Worker.run(ThreadPoolExecutor.java:617)
	at java.lang.Thread.run(Thread.java:745)
... Removed 10 stack frames]]>
    </failure>
  </testcase> <!-- f1 -->
  <testcase name="testingParameters" time="0.001" classname="TestNGAnnotations.AnnotationSequence">
    <skipped/>
  </testcase> <!-- testingParameters -->
  <testcase name="f" time="0.001" classname="TestNGAnnotations.AnnotationSequence"/>
</testsuite> <!-- Sequence Test -->
